[32m2024-01-30 12:20:37 -0500[0m - dagster - [34mDEBUG[0m - __ASSET_JOB - 1e23663d-87f0-4c59-b6c6-cde1b860db4c - 73291 - LOGS_CAPTURED - Started capturing logs in process (pid: 73291).
[32m2024-01-30 12:20:37 -0500[0m - dagster - [34mDEBUG[0m - __ASSET_JOB - 1e23663d-87f0-4c59-b6c6-cde1b860db4c - 73291 - config_validation - STEP_START - Started execution of step "config_validation".
[32m2024-01-30 12:20:37 -0500[0m - dagster - [34mERROR[0m - [31m__ASSET_JOB - 1e23663d-87f0-4c59-b6c6-cde1b860db4c - 73291 - config_validation - STEP_FAILURE - Execution of step "config_validation" failed.

dagster._core.errors.DagsterExecutionStepExecutionError: Error occurred while executing op "config_validation"::

NameError: name 'logging' is not defined

Stack Trace:
  File "/Users/dkogan/.pyenv/versions/3.10.0/lib/python3.10/site-packages/dagster/_core/execution/plan/utils.py", line 54, in op_execution_error_boundary
    yield
  File "/Users/dkogan/.pyenv/versions/3.10.0/lib/python3.10/site-packages/dagster/_utils/__init__.py", line 467, in iterate_with_context
    next_output = next(iterator)
  File "/Users/dkogan/.pyenv/versions/3.10.0/lib/python3.10/site-packages/dagster/_core/execution/plan/compute_generator.py", line 131, in _coerce_op_compute_fn_to_iterator
    result = invoke_compute_fn(
  File "/Users/dkogan/.pyenv/versions/3.10.0/lib/python3.10/site-packages/dagster/_core/execution/plan/compute_generator.py", line 125, in invoke_compute_fn
    return fn(context, **args_to_pass) if context_arg_provided else fn(**args_to_pass)
  File "/Users/dkogan/dagster-stratify/dagster_stratify/assets.py", line 11, in config_validation
    my_logger = logging.getLogger("my_logger")
[0m
