[32m2024-01-29 11:32:35 -0500[0m - dagster - [34mDEBUG[0m - __ASSET_JOB - d2d81dba-74b5-40a7-9f77-0ae44facf824 - 42777 - LOGS_CAPTURED - Started capturing logs in process (pid: 42777).
[32m2024-01-29 11:32:35 -0500[0m - dagster - [34mDEBUG[0m - __ASSET_JOB - d2d81dba-74b5-40a7-9f77-0ae44facf824 - 42777 - config_validate - STEP_START - Started execution of step "config_validate".
[32m2024-01-29 11:32:35 -0500[0m - dagster - [34mERROR[0m - [31m__ASSET_JOB - d2d81dba-74b5-40a7-9f77-0ae44facf824 - 42777 - config_validate - STEP_FAILURE - Execution of step "config_validate" failed.

dagster._core.errors.DagsterExecutionStepExecutionError: Error occurred while executing op "config_validate"::

requests.exceptions.ConnectionError: HTTPConnectionPool(host='localhost', port=80000): Max retries exceeded with url: /config_validate (Caused by NewConnectionError('<urllib3.connection.HTTPConnection object at 0x108d7b490>: Failed to establish a new connection: [Errno 8] nodename nor servname provided, or not known'))

Stack Trace:
  File "/Users/dkogan/.pyenv/versions/3.10.0/lib/python3.10/site-packages/dagster/_core/execution/plan/utils.py", line 54, in op_execution_error_boundary
    yield
  File "/Users/dkogan/.pyenv/versions/3.10.0/lib/python3.10/site-packages/dagster/_utils/__init__.py", line 467, in iterate_with_context
    next_output = next(iterator)
  File "/Users/dkogan/.pyenv/versions/3.10.0/lib/python3.10/site-packages/dagster/_core/execution/plan/compute_generator.py", line 131, in _coerce_op_compute_fn_to_iterator
    result = invoke_compute_fn(
  File "/Users/dkogan/.pyenv/versions/3.10.0/lib/python3.10/site-packages/dagster/_core/execution/plan/compute_generator.py", line 125, in invoke_compute_fn
    return fn(context, **args_to_pass) if context_arg_provided else fn(**args_to_pass)
  File "/Users/dkogan/dagster-stratify/dagster_stratify/assets.py", line 14, in config_validate
    response = requests.post(api_url, json={})
  File "/Users/dkogan/.pyenv/versions/3.10.0/lib/python3.10/site-packages/requests/api.py", line 116, in post
    return request('post', url, data=data, json=json, **kwargs)
  File "/Users/dkogan/.pyenv/versions/3.10.0/lib/python3.10/site-packages/requests/api.py", line 60, in request
    return session.request(method=method, url=url, **kwargs)
  File "/Users/dkogan/.pyenv/versions/3.10.0/lib/python3.10/site-packages/requests/sessions.py", line 533, in request
    resp = self.send(prep, **send_kwargs)
  File "/Users/dkogan/.pyenv/versions/3.10.0/lib/python3.10/site-packages/requests/sessions.py", line 646, in send
    r = adapter.send(request, **kwargs)
  File "/Users/dkogan/.pyenv/versions/3.10.0/lib/python3.10/site-packages/requests/adapters.py", line 516, in send
    raise ConnectionError(e, request=request)

The above exception occurred during handling of the following exception:
urllib3.exceptions.MaxRetryError: HTTPConnectionPool(host='localhost', port=80000): Max retries exceeded with url: /config_validate (Caused by NewConnectionError('<urllib3.connection.HTTPConnection object at 0x108d7b490>: Failed to establish a new connection: [Errno 8] nodename nor servname provided, or not known'))

Stack Trace:
  File "/Users/dkogan/.pyenv/versions/3.10.0/lib/python3.10/site-packages/requests/adapters.py", line 439, in send
    resp = conn.urlopen(
  File "/Users/dkogan/.pyenv/versions/3.10.0/lib/python3.10/site-packages/urllib3/connectionpool.py", line 637, in urlopen
    retries = retries.increment(method, url, error=e, _pool=self,
  File "/Users/dkogan/.pyenv/versions/3.10.0/lib/python3.10/site-packages/urllib3/util/retry.py", line 399, in increment
    raise MaxRetryError(_pool, url, error or ResponseError(cause))

The above exception occurred during handling of the following exception:
urllib3.exceptions.NewConnectionError: <urllib3.connection.HTTPConnection object at 0x108d7b490>: Failed to establish a new connection: [Errno 8] nodename nor servname provided, or not known

Stack Trace:
  File "/Users/dkogan/.pyenv/versions/3.10.0/lib/python3.10/site-packages/urllib3/connectionpool.py", line 597, in urlopen
    httplib_response = self._make_request(conn, method, url,
  File "/Users/dkogan/.pyenv/versions/3.10.0/lib/python3.10/site-packages/urllib3/connectionpool.py", line 354, in _make_request
    conn.request(method, url, **httplib_request_kw)
  File "/Users/dkogan/.pyenv/versions/3.10.0/lib/python3.10/http/client.py", line 1276, in request
    self._send_request(method, url, body, headers, encode_chunked)
  File "/Users/dkogan/.pyenv/versions/3.10.0/lib/python3.10/http/client.py", line 1322, in _send_request
    self.endheaders(body, encode_chunked=encode_chunked)
  File "/Users/dkogan/.pyenv/versions/3.10.0/lib/python3.10/http/client.py", line 1271, in endheaders
    self._send_output(message_body, encode_chunked=encode_chunked)
  File "/Users/dkogan/.pyenv/versions/3.10.0/lib/python3.10/http/client.py", line 1031, in _send_output
    self.send(msg)
  File "/Users/dkogan/.pyenv/versions/3.10.0/lib/python3.10/http/client.py", line 969, in send
    self.connect()
  File "/Users/dkogan/.pyenv/versions/3.10.0/lib/python3.10/site-packages/urllib3/connection.py", line 181, in connect
    conn = self._new_conn()
  File "/Users/dkogan/.pyenv/versions/3.10.0/lib/python3.10/site-packages/urllib3/connection.py", line 167, in _new_conn
    raise NewConnectionError(

The above exception occurred during handling of the following exception:
socket.gaierror: [Errno 8] nodename nor servname provided, or not known

Stack Trace:
  File "/Users/dkogan/.pyenv/versions/3.10.0/lib/python3.10/site-packages/urllib3/connection.py", line 158, in _new_conn
    conn = connection.create_connection(
  File "/Users/dkogan/.pyenv/versions/3.10.0/lib/python3.10/site-packages/urllib3/util/connection.py", line 57, in create_connection
    for res in socket.getaddrinfo(host, port, family, socket.SOCK_STREAM):
  File "/Users/dkogan/.pyenv/versions/3.10.0/lib/python3.10/socket.py", line 955, in getaddrinfo
    for res in _socket.getaddrinfo(host, port, family, type, proto, flags):
[0m
