[32m2024-01-29 11:19:49 -0500[0m - dagster - [34mDEBUG[0m - __ASSET_JOB - ca0fb284-72c5-460d-bff0-8fd865926d4f - 41094 - LOGS_CAPTURED - Started capturing logs in process (pid: 41094).
[32m2024-01-29 11:19:49 -0500[0m - dagster - [34mDEBUG[0m - __ASSET_JOB - ca0fb284-72c5-460d-bff0-8fd865926d4f - 41094 - config_validate - STEP_START - Started execution of step "config_validate".
[32m2024-01-29 11:19:49 -0500[0m - dagster - [34mERROR[0m - [31m__ASSET_JOB - ca0fb284-72c5-460d-bff0-8fd865926d4f - 41094 - config_validate - STEP_FAILURE - Execution of step "config_validate" failed.

dagster._core.errors.DagsterExecutionStepExecutionError: Error occurred while executing op "config_validate"::

requests.exceptions.InvalidURL: Failed to parse: http://localhost:80000/config_validate

Stack Trace:
  File "/Users/dkogan/.pyenv/versions/3.10.0/lib/python3.10/site-packages/dagster/_core/execution/plan/utils.py", line 54, in op_execution_error_boundary
    yield
  File "/Users/dkogan/.pyenv/versions/3.10.0/lib/python3.10/site-packages/dagster/_utils/__init__.py", line 467, in iterate_with_context
    next_output = next(iterator)
  File "/Users/dkogan/.pyenv/versions/3.10.0/lib/python3.10/site-packages/dagster/_core/execution/plan/compute_generator.py", line 131, in _coerce_op_compute_fn_to_iterator
    result = invoke_compute_fn(
  File "/Users/dkogan/.pyenv/versions/3.10.0/lib/python3.10/site-packages/dagster/_core/execution/plan/compute_generator.py", line 125, in invoke_compute_fn
    return fn(context, **args_to_pass) if context_arg_provided else fn(**args_to_pass)
  File "/Users/dkogan/dagster-stratify/dagster_stratify/assets.py", line 16, in config_validate
    response = requests.post(api_url, json=config)
  File "/Users/dkogan/.pyenv/versions/3.10.0/lib/python3.10/site-packages/requests/api.py", line 115, in post
    return request("post", url, data=data, json=json, **kwargs)
  File "/Users/dkogan/.pyenv/versions/3.10.0/lib/python3.10/site-packages/requests/api.py", line 59, in request
    return session.request(method=method, url=url, **kwargs)
  File "/Users/dkogan/.pyenv/versions/3.10.0/lib/python3.10/site-packages/requests/sessions.py", line 575, in request
    prep = self.prepare_request(req)
  File "/Users/dkogan/.pyenv/versions/3.10.0/lib/python3.10/site-packages/requests/sessions.py", line 486, in prepare_request
    p.prepare(
  File "/Users/dkogan/.pyenv/versions/3.10.0/lib/python3.10/site-packages/requests/models.py", line 368, in prepare
    self.prepare_url(url, params)
  File "/Users/dkogan/.pyenv/versions/3.10.0/lib/python3.10/site-packages/requests/models.py", line 436, in prepare_url
    raise InvalidURL(*e.args)

The above exception occurred during handling of the following exception:
urllib3.exceptions.LocationParseError: Failed to parse: http://localhost:80000/config_validate

Stack Trace:
  File "/Users/dkogan/.pyenv/versions/3.10.0/lib/python3.10/site-packages/requests/models.py", line 434, in prepare_url
    scheme, auth, host, port, path, query, fragment = parse_url(url)
  File "/Users/dkogan/.pyenv/versions/3.10.0/lib/python3.10/site-packages/urllib3/util/url.py", line 451, in parse_url
    raise LocationParseError(source_url) from e

The above exception was caused by the following exception:
urllib3.exceptions.LocationParseError: Failed to parse: http://localhost:80000/config_validate

Stack Trace:
  File "/Users/dkogan/.pyenv/versions/3.10.0/lib/python3.10/site-packages/urllib3/util/url.py", line 436, in parse_url
    raise LocationParseError(url)
[0m
