[32m2024-01-30 16:10:04 -0500[0m - dagster - [34mDEBUG[0m - __ASSET_JOB - 77de8090-0fda-408c-892e-8ac823420101 - 82364 - LOGS_CAPTURED - Started capturing logs in process (pid: 82364).
[32m2024-01-30 16:10:04 -0500[0m - dagster - [34mDEBUG[0m - __ASSET_JOB - 77de8090-0fda-408c-892e-8ac823420101 - 82364 - config_validation - STEP_START - Started execution of step "config_validation".
[32m2024-01-30 16:11:06 -0500[0m - dagster - [34mERROR[0m - [31m__ASSET_JOB - 77de8090-0fda-408c-892e-8ac823420101 - 82364 - config_validation - STEP_FAILURE - Execution of step "config_validation" failed.

dagster._core.errors.DagsterExecutionInterruptedError

Stack Trace:
  File "/Users/dkogan/.pyenv/versions/3.10.0/lib/python3.10/site-packages/dagster/_core/execution/plan/execute_plan.py", line 286, in dagster_event_sequence_for_step
    for step_event in check.generator(step_events):
  File "/Users/dkogan/.pyenv/versions/3.10.0/lib/python3.10/site-packages/dagster/_core/execution/plan/execute_step.py", line 487, in core_dagster_event_sequence_for_step
    for user_event in _step_output_error_checked_user_event_sequence(
  File "/Users/dkogan/.pyenv/versions/3.10.0/lib/python3.10/site-packages/dagster/_core/execution/plan/execute_step.py", line 169, in _step_output_error_checked_user_event_sequence
    for user_event in user_event_sequence:
  File "/Users/dkogan/.pyenv/versions/3.10.0/lib/python3.10/site-packages/dagster/_core/execution/plan/execute_step.py", line 95, in _process_asset_results_to_events
    for user_event in user_event_sequence:
  File "/Users/dkogan/.pyenv/versions/3.10.0/lib/python3.10/site-packages/dagster/_core/execution/plan/compute.py", line 212, in execute_core_compute
    for step_output in _yield_compute_results(step_context, inputs, compute_fn, compute_context):
  File "/Users/dkogan/.pyenv/versions/3.10.0/lib/python3.10/site-packages/dagster/_core/execution/plan/compute.py", line 181, in _yield_compute_results
    for event in iterate_with_context(
  File "/Users/dkogan/.pyenv/versions/3.10.0/lib/python3.10/site-packages/dagster/_utils/__init__.py", line 467, in iterate_with_context
    next_output = next(iterator)
  File "/Users/dkogan/.pyenv/versions/3.10.0/lib/python3.10/site-packages/dagster/_core/execution/plan/compute_generator.py", line 131, in _coerce_op_compute_fn_to_iterator
    result = invoke_compute_fn(
  File "/Users/dkogan/.pyenv/versions/3.10.0/lib/python3.10/site-packages/dagster/_core/execution/plan/compute_generator.py", line 125, in invoke_compute_fn
    return fn(context, **args_to_pass) if context_arg_provided else fn(**args_to_pass)
  File "/Users/dkogan/dagster-stratify/dagster_stratify/assets.py", line 16, in config_validation
    subprocess.run(command_list)
  File "/Users/dkogan/.pyenv/versions/3.10.0/lib/python3.10/subprocess.py", line 503, in run
    stdout, stderr = process.communicate(input, timeout=timeout)
  File "/Users/dkogan/.pyenv/versions/3.10.0/lib/python3.10/subprocess.py", line 1141, in communicate
    self.wait()
  File "/Users/dkogan/.pyenv/versions/3.10.0/lib/python3.10/subprocess.py", line 1204, in wait
    return self._wait(timeout=timeout)
  File "/Users/dkogan/.pyenv/versions/3.10.0/lib/python3.10/subprocess.py", line 1938, in _wait
    (pid, sts) = self._try_wait(0)
  File "/Users/dkogan/.pyenv/versions/3.10.0/lib/python3.10/subprocess.py", line 1896, in _try_wait
    (pid, sts) = os.waitpid(self.pid, wait_flags)
  File "/Users/dkogan/.pyenv/versions/3.10.0/lib/python3.10/site-packages/dagster/_utils/interrupts.py", line 82, in _new_signal_handler
    raise error_cls()
[0m
